<?xml version="1.0"?>
<robot xmlns:xacro="http://www.ros.org/wiki/xacro" name="robot_arm" >	

	<xacro:arg name="namespace" default="robot1"/>

    <!-- ################# Base Link ################# -->
    <link name="$(arg namespace)_base_link">
        <inertial>
            <origin xyz="-0.038799 5.6771E-08 0.039037" rpy="0 0 0"/>
            <mass value="4.037"/>
            <inertia
                ixx="0.0047485"
                ixy="6.9936E-08"
                ixz="2.5452E-06"
                iyy="0.01214"
                iyz="-4.4737E-10"
                izz="0.015979"/>
        </inertial>
        <visual>
            <origin xyz="0 0 0" rpy="0 0 0"/>
            <geometry>
                <mesh filename="package://arm_control/description/meshes/base_link.STL"/>
            </geometry>
            <material name="">
                <color rgba="0.75294 0.75294 0.75294 1"/>
            </material>
        </visual>
        <collision>
            <origin xyz="0 0 0" rpy="0 0 0"/>
            <geometry>
                <mesh filename="package://arm_control/description/meshes/base_link.STL"/>
            </geometry>
        </collision>
    </link>

    <!-- ################# Arm Link 1 ################# -->
    <link name="$(arg namespace)_Link1">
        <inertial>
            <origin xyz="4.7367E-05 0.10068 0.020948" rpy="0 0 0" />
            <mass value="0.97007" />
            <inertia
                ixx="0.0010278"
                ixy="-3.2684E-07"
                ixz="-5.2705E-07"
                iyy="0.001187"
                iyz="2.9768E-06"
                izz="0.00070562" />
        </inertial>
        <visual>
            <origin xyz="0 0 0" rpy="0 0 0" />
            <geometry>
                <mesh filename="package://arm_control/description/meshes/Link1.STL" />
            </geometry>
            <material name="">
                <color rgba="0.75294 0.75294 0.75294 1" />
            </material>
        </visual>
        <collision>
            <origin xyz="0 0 0" rpy="0 0 0" />
            <geometry>
                <mesh filename="package://arm_control/description/meshes/Link1.STL" />
            </geometry>
        </collision>
    </link>
    <joint name="$(arg namespace)_J1" type="revolute">
        <origin xyz="0 0 0.0059964" rpy="1.5708 0 0" />
        <parent link="$(arg namespace)_base_link" />
        <child link="$(arg namespace)_Link1" />
        <axis xyz="0 -1 0" />
        <limit lower="-3.14" upper="3.14" effort="10" velocity="10" />
    </joint>

    <!-- ################# Arm Link 2 ################# -->
    <link name="$(arg namespace)_Link2">
        <inertial>
            <origin xyz="-1.46417876076469E-06 0.117729185705366 -0.0378668860722142" rpy="0 0 0" />
            <mass value="0.577415758791343" />
            <inertia
                ixx="0.0036047406071256"
                ixy="6.4776030540196E-08"
                ixz="1.20114307201048E-07"
                iyy="0.000412136925722125"
                iyz="-1.52201263463148E-05"
                izz="0.00360983067595921" />
        </inertial>
        <visual>
            <origin xyz="0 0 0" rpy="0 0 0" />
            <geometry>
                <mesh filename="package://arm_control/description/meshes/Link2.STL" />
            </geometry>
            <material name="">
                <color rgba="0.752941176470588 0.752941176470588 0.752941176470588 1" />
            </material>
        </visual>
        <collision>
            <origin xyz="0 0 0" rpy="0 0 0" />
            <geometry>
                <mesh filename="package://arm_control/description/meshes/Link2.STL" />
            </geometry>
        </collision>
    </link>
    <joint name="$(arg namespace)_J2" type="revolute">
        <origin xyz="0 0.134 0" rpy="0 0 0" />
        <parent link="$(arg namespace)_Link1" />
        <child link="$(arg namespace)_Link2" />
        <axis xyz="0 0 -1" />
        <limit lower="-1.57" upper="1.57" effort="0" velocity="0" />
    </joint>

    <!-- ################# Arm Link 3 ################# -->
    <link name="$(arg namespace)_Link3">
        <inertial>
            <origin xyz="-0.0328882111255075 8.45678153449381E-07 -0.0129958354849986" rpy="0 0 0" />
            <mass value="0.251663957012598" />
            <inertia
                ixx="6.72067273429369E-05"
                ixy="4.83904268931055E-09"
                ixz="-2.18784718458254E-08"
                iyy="0.000125285505512965"
                iyz="3.49876261972673E-15"
                izz="0.000132327236956115" />
        </inertial>
        <visual>
            <origin xyz="0 0 0" rpy="0 0 0" />
            <geometry>
                <mesh filename="package://arm_control/description/meshes/Link3.STL" />
            </geometry>
            <material name="">
                <color rgba="0.752941176470588 0.752941176470588 0.752941176470588 1" />
            </material>
        </visual>
        <collision>
            <origin xyz="0 0 0" rpy="0 0 0" />
            <geometry>
                <mesh filename="package://arm_control/description/meshes/Link3.STL" />
            </geometry>
        </collision>
    </link>
    <joint name="$(arg namespace)_J3" type="revolute">
        <origin xyz="0 0.322 0" rpy="0 0 0" />
        <parent link="$(arg namespace)_Link2" />
        <child link="$(arg namespace)_Link3" />
        <axis xyz="0 0 -1" />
        <limit lower="0" upper="3.14" effort="10" velocity="10" />
    </joint>

    <!-- ################# Arm Link 4 ################# -->
    <link name="$(arg namespace)_Link4">
        <inertial>
            <origin xyz="0.099774322521478 -0.000172379735017603 0.00118588583890608" rpy="0 0 0" />
            <mass value="0.356013835274962" />
            <inertia
            ixx="0.000270166646517537"
            ixy="-2.8024785401758E-07"
            ixz="-2.10227432082948E-05"
            iyy="0.00116383385329662"
            iyz="-8.06758147658775E-08"
            izz="0.000994142094397537" />
        </inertial>
        <visual>
            <origin xyz="0 0 0" rpy="0 0 0" />
            <geometry>
                <mesh filename="package://arm_control/description/meshes/Link4.STL" />
            </geometry>
            <material name="">
                <color rgba="0.752941176470588 0.752941176470588 0.752941176470588 1" />
            </material>
        </visual>
        <collision>
            <origin xyz="0 0 0" rpy="0 0 0" />
            <geometry>
                <mesh filename="package://arm_control/description/meshes/Link4.STL" />
            </geometry>
        </collision>
    </link>
    <joint name="$(arg namespace)_J4" type="revolute">
        <origin xyz="0.03 0 0" rpy="0 0 0" />
        <parent link="$(arg namespace)_Link3" />
        <child link="$(arg namespace)_Link4" />
        <axis xyz="1 0 0" />
        <limit lower="-3.14" upper="3.14" effort="10" velocity="10" />
    </joint>

    <!-- ################# Arm Link 5 ################# -->
    <link name="$(arg namespace)_Link5">
        <inertial>
            <origin xyz="-0.00745918037903059 1.44166386780165E-05 -0.00833926520904369" rpy="0 0 0" />
            <mass value="0.175482504091363" />
            <inertia
                ixx="5.10545535580843E-05"
                ixy="-5.97452165278952E-08"
                ixz="1.44581078477868E-06"
                iyy="0.000107503817667908"
                iyz="5.76444930838975E-09"
                izz="0.000100856356891325" />
        </inertial>
        <visual>
            <origin xyz="0 0 0" rpy="0 0 0" />
            <geometry>
                <mesh filename="package://arm_control/description/meshes/Link5.STL" />
            </geometry>
            <material name="">
                <color rgba="0.752941176470588 0.752941176470588 0.752941176470588 1" />
            </material>
        </visual>
        <collision>
            <origin xyz="0 0 0" rpy="0 0 0" />
            <geometry>
                <mesh filename="package://arm_control/description/meshes/Link5.STL" />
            </geometry>
        </collision>
    </link>
    <joint name="$(arg namespace)_J5" type="revolute">
        <origin xyz="0.20275 0 0" rpy="3.1416 0 0" />
        <parent link="$(arg namespace)_Link4" />
        <child link="$(arg namespace)_Link5" />
        <axis xyz="0 0 -1" />
        <limit lower="-1.57" upper="1.57" effort="10" velocity="10" />
    </joint>

    <!-- ################# Arm Link 6 ################# -->
    <link name="$(arg namespace)_Link6">
        <inertial>
            <origin xyz="0.00833988976417116 0.000113774503086972 -1.32769045757541E-10" rpy="0 0 0" />
            <mass value="0.0135263682638669" />
            <inertia
                ixx="2.02217071919662E-06"
                ixy="5.87479646435333E-09"
                ixz="-8.97698504642466E-15"
                iyy="1.3204524747585E-06"
                iyz="-1.52963229446115E-14"
                izz="1.3036592664547E-06" />
        </inertial>
        <visual>
            <origin xyz="0 0 0" rpy="0 0 0" />
            <geometry>
                <mesh filename="package://arm_control/description/meshes/Link6.STL" />
            </geometry>
            <material name="">
                <color rgba="0.752941176470588 0.752941176470588 0.752941176470588 1" />
            </material>
        </visual>
        <collision>
            <origin xyz="0 0 0" rpy="0 0 0" />
            <geometry>
                <mesh filename="package://arm_control/description/meshes/Link6.STL" />
            </geometry>
        </collision>
    </link>
    <joint name="$(arg namespace)_J6" type="revolute">
        <origin xyz="0.02825 0 -0.01" rpy="-3.1416 0 0" />
        <parent link="$(arg namespace)_Link5" />
        <child link="$(arg namespace)_Link6" />
        <axis xyz="1 0 0" />
        <limit lower="-3.14" upper="3.14" effort="10" velocity="10" />
    </joint>
</robot>