<?xml version="1.0" encoding="utf-8"?>
<!-- This URDF was automatically created by SolidWorks to URDF Exporter! Originally created by Stephen Brawner (brawner@gmail.com) 
     Commit Version: 1.6.0-4-g7f85cfe  Build Version: 1.6.7995.38578
     For more information, please see http://wiki.ros.org/sw_urdf_exporter -->
<robot
  name="robotic_arm">
  <link
    name="base_link">
    <inertial>
      <origin
        xyz="-0.064318 0.039257 -2.9623E-07"
        rpy="0 0 0" />
      <mass
        value="0.83438" />
      <inertia
        ixx="0.00098057"
        ixy="2.6509E-06"
        ixz="-6.484E-08"
        iyy="0.0033643"
        iyz="3.8674E-10"
        izz="0.0027303" />
    </inertial>
    <visual>
      <origin
        xyz="0 0 0"
        rpy="0 0 0" />
      <geometry>
        <mesh
          filename="package://arm_control/description/meshes/base_link.STL" />
      </geometry>
      <material
        name="">
        <color
          rgba="0.75294 0.75294 0.75294 1" />
      </material>
    </visual>
    <collision>
      <origin
        xyz="0 0 0"
        rpy="0 0 0" />
      <geometry>
        <mesh
          filename="package://arm_control/description/meshes/base_link.STL" />
      </geometry>
    </collision>
  </link>
  <link
    name="Link2">
    <inertial>
      <origin
        xyz="4.7367E-05 0.10668 0.020948"
        rpy="0 0 0" />
      <mass
        value="0.97007" />
      <inertia
        ixx="0.0010278"
        ixy="-3.2684E-07"
        ixz="-5.2705E-07"
        iyy="0.001187"
        iyz="2.9768E-06"
        izz="0.00070562" />
    </inertial>
    <visual>
      <origin
        xyz="0 0 0"
        rpy="0 0 0" />
      <geometry>
        <mesh
          filename="package://arm_control/description/meshes/Link2.STL" />
      </geometry>
      <material
        name="">
        <color
          rgba="0.75294 0.75294 0.75294 1" />
      </material>
    </visual>
    <collision>
      <origin
        xyz="0 0 0"
        rpy="0 0 0" />
      <geometry>
        <mesh
          filename="package://arm_control/description/meshes/Link2.STL" />
      </geometry>
    </collision>
  </link>
  <joint
    name="J1"
    type="revolute">
    <origin
      xyz="0 0 0"
      rpy="1.5708 0 0" />
    <parent
      link="base_link" />
    <child
      link="Link2" />
    <axis
      xyz="0 1 0" />
    <limit
      lower="0"
      upper="6.28"
      effort="10"
      velocity="10" />
  </joint>
  <link
    name="Link3">
    <inertial>
      <origin
        xyz="-1.46417876076533E-06 0.117729185705366 -0.0378668860722142"
        rpy="0 0 0" />
      <mass
        value="0.577415758791342" />
      <inertia
        ixx="0.0036047406071256"
        ixy="6.47760305401987E-08"
        ixz="1.20114307201049E-07"
        iyy="0.000412136925722125"
        iyz="-1.52201263463148E-05"
        izz="0.00360983067595921" />
    </inertial>
    <visual>
      <origin
        xyz="0 0 0"
        rpy="0 0 0" />
      <geometry>
        <mesh
          filename="package://arm_control/description/meshes/Link3.STL" />
      </geometry>
      <material
        name="">
        <color
          rgba="0.752941176470588 0.752941176470588 0.752941176470588 1" />
      </material>
    </visual>
    <collision>
      <origin
        xyz="0 0 0"
        rpy="0 0 0" />
      <geometry>
        <mesh
          filename="package://arm_control/description/meshes/Link3.STL" />
      </geometry>
    </collision>
  </link>
  <joint
    name="J2"
    type="revolute">
    <origin
      xyz="0 0.14 0"
      rpy="0 0 0" />
    <parent
      link="Link2" />
    <child
      link="Link3" />
    <axis
      xyz="0 0 1" />
    <limit
      lower="-1.570796"
      upper="1.570796"
      effort="10"
      velocity="10" />
  </joint>
  <link
    name="Link4">
    <inertial>
      <origin
        xyz="-0.0328882111255075 8.45678153449381E-07 -0.0129958354849986"
        rpy="0 0 0" />
      <mass
        value="0.251663957012598" />
      <inertia
        ixx="6.72067273429369E-05"
        ixy="4.83904268931015E-09"
        ixz="-2.18784718458252E-08"
        iyy="0.000125285505512965"
        iyz="3.49876226111741E-15"
        izz="0.000132327236956115" />
    </inertial>
    <visual>
      <origin
        xyz="0 0 0"
        rpy="0 0 0" />
      <geometry>
        <mesh
          filename="package://arm_control/description/meshes/Link4.STL" />
      </geometry>
      <material
        name="">
        <color
          rgba="0.752941176470588 0.752941176470588 0.752941176470588 1" />
      </material>
    </visual>
    <collision>
      <origin
        xyz="0 0 0"
        rpy="0 0 0" />
      <geometry>
        <mesh
          filename="package://arm_control/description/meshes/Link4.STL" />
      </geometry>
    </collision>
  </link>
  <joint
    name="J3"
    type="revolute">
    <origin
      xyz="0 0.322 0"
      rpy="0 0 0" />
    <parent
      link="Link3" />
    <child
      link="Link4" />
    <axis
      xyz="0 0 1" />
    <limit
      lower="-1.5708"
      upper="1.5708"
      effort="10"
      velocity="10" />
  </joint>
  <link
    name="Link5">
    <inertial>
      <origin
        xyz="0.0959443943416938 -0.000157341805081312 0.00107507946414181"
        rpy="0 0 0" />
      <mass
        value="0.300029724080392" />
      <inertia
        ixx="0.000212980238434561"
        ixy="-2.15575269645667E-07"
        ixz="-1.61941970571356E-05"
        iyy="0.000911097635242398"
        iyz="-6.20583191016507E-08"
        izz="0.000780565263645566" />
    </inertial>
    <visual>
      <origin
        xyz="0 0 0"
        rpy="0 0 0" />
      <geometry>
        <mesh
          filename="package://arm_control/description/meshes/Link5.STL" />
      </geometry>
      <material
        name="">
        <color
          rgba="0.752941176470588 0.752941176470588 0.752941176470588 1" />
      </material>
    </visual>
    <collision>
      <origin
        xyz="0 0 0"
        rpy="0 0 0" />
      <geometry>
        <mesh
          filename="package://arm_control/description/meshes/Link5.STL" />
      </geometry>
    </collision>
  </link>
  <joint
    name="J4"
    type="revolute">
    <origin
      xyz="0.03 0 0"
      rpy="0 0 0" />
    <parent
      link="Link4" />
    <child
      link="Link5" />
    <axis
      xyz="1 0 0" />
    <limit
      lower="0"
      upper="6.28"
      effort="10"
      velocity="10" />
  </joint>
  <link
    name="Link6">
    <inertial>
      <origin
        xyz="-0.00928310094878421 1.2483555139553E-05 -0.00856165178953772"
        rpy="0 0 0" />
      <mass
        value="0.155889261418066" />
      <inertia
        ixx="4.28549661625321E-05"
        ixy="-4.59578584586532E-08"
        ixz="1.10962985052539E-06"
        iyy="9.76511984630011E-05"
        iyz="4.4341918291842E-09"
        izz="9.25375630975331E-05" />
    </inertial>
    <visual>
      <origin
        xyz="0 0 0"
        rpy="0 0 0" />
      <geometry>
        <mesh
          filename="package://arm_control/description/meshes/Link6.STL" />
      </geometry>
      <material
        name="">
        <color
          rgba="0.752941176470588 0.752941176470588 0.752941176470588 1" />
      </material>
    </visual>
    <collision>
      <origin
        xyz="0 0 0"
        rpy="0 0 0" />
      <geometry>
        <mesh
          filename="package://arm_control/description/meshes/Link6.STL" />
      </geometry>
    </collision>
  </link>
  <joint
    name="J5"
    type="revolute">
    <origin
      xyz="0.20275 0 0"
      rpy="3.1416 0 0" />
    <parent
      link="Link5" />
    <child
      link="Link6" />
    <axis
      xyz="0 0 1" />
    <limit
      lower="-1.570796"
      upper="1.570796"
      effort="10"
      velocity="10" />
  </joint>
  <link
    name="Link7">
    <inertial>
      <origin
        xyz="0.00833988976417116 0.000113774503086972 -1.32769045757541E-10"
        rpy="0 0 0" />
      <mass
        value="0.0135263682638669" />
      <inertia
        ixx="2.02217071919662E-06"
        ixy="5.87479646435333E-09"
        ixz="-8.97698504636946E-15"
        iyy="1.3204524747585E-06"
        iyz="-1.52963229443247E-14"
        izz="1.3036592664547E-06" />
    </inertial>
    <visual>
      <origin
        xyz="0 0 0"
        rpy="0 0 0" />
      <geometry>
        <mesh
          filename="package://arm_control/description/meshes/Link7.STL" />
      </geometry>
      <material
        name="">
        <color
          rgba="0.752941176470588 0.752941176470588 0.752941176470588 1" />
      </material>
    </visual>
    <collision>
      <origin
        xyz="0 0 0"
        rpy="0 0 0" />
      <geometry>
        <mesh
          filename="package://arm_control/description/meshes/Link7.STL" />
      </geometry>
    </collision>
  </link>
  <joint
    name="J6"
    type="revolute">
    <origin
      xyz="0.02825 0 -0.01"
      rpy="-3.1416 0 0" />
    <parent
      link="Link6" />
    <child
      link="Link7" />
    <axis
      xyz="1 0 0" />
    <limit
      lower="0"
      upper="6.28"
      effort="10"
      velocity="10" />
  </joint>
</robot>
